Workbook
Name dwsrf_funding_tracker_all_projects: dwsrf_tracker!$A$1:$R$14802

Sheet metadata
A1: Tab | B1: Description | C1: Source | D1: URL | E1: Notes
A2: tot_allotment | B2: Allotment summary | C2: Katy compiled
A3: overtime | B3: Data of # proj and amount overtime | C3: CRS | D3: https://www.congress.gov/crs-product/R48066
A4: CW_23_cap | B4: Allotment for 23 | C4: EPA | D4: https://www.epa.gov/system/files/documents/2023-03/fy2023-cwsrf-base-allotment.pdf
A5: DW_23_cap | B5: Allotment for 23 | C5: EPA | D5: https://www.epa.gov/system/files/documents/2023-04/Final_FY23%20DWSRF%20Allotment%20Memo%20and%20Attachments_April%202023.pdf
A6: cds_23 | B6: Earmarks | C6: Congress | D6: https://www.appropriations.senate.gov/imo/media/doc/INTERIOR_DISCL_20221218.pdf | E6: Katy digitized
A7: CW_24_cap | B7: Allotment for 24 | C7: EPA | D7: https://www.epa.gov/system/files/documents/2024-04/fy24-joint-srf-allotments-memorandum-attachments.pdf
A8: DW_24_cap | B8: Allotment for 24 | C8: EPA | D8: https://www.epa.gov/system/files/documents/2024-04/fy24-joint-srf-allotments-memorandum-attachments.pdf
A9: cds_24 | B9: Earmarks | C9: Congress | E9: EPIC digitized | F9: https://docs.google.com/spreadsheets/d/1GMUcOXnIPlLiP-Oh_cEPAnCZPpCLsGI-/edit?gid=1942082838#gid=1942082838
A10: dwsrf_tracker | B10: All tracker data | C10: IUPs/PPLs from EPIC

Sheet tot_allotment
B1: FY21 | C1: FY22 | D1: FY23 | E1: FY24 | F1: FY25
B2: CW | C2: CW | D2: CW | E2: CW | F2: CW
A3: Funds Available to States | D3: 757737000 | E3: 824644000
A4: Tribal Set-Aside | D4: 15515000 | E4: 16880000
A5: Clean Watersheds Needs Survery | D5: 1500000 | E5: 1500000
A6: National American Iron & Steel Administrative Set-Aside | D6: 1000358 | E6: 1000733
A7: CDS | D7: 863108642 | E7: 787652267
A8: CDS Administration | E8: 7184000
A9: Total Appropriation | D9: 1638861000 | E9: 1638861000
A10: Base - set asides: | D10: =D9-SUM(D4:D6) -> 1620845642 | E10: =E9-SUM(E4:E6) -> 1619480267
B12: DW | C12: DW | D12: DW | E12: DW | F12: DW
A13: Funds Available to States | D13: 493785000 | E13: 466058000
A14: Tribal Set-Aside | D14: 10332000 | E14: 9767000
A15: Monitoring for Unregulated Contaminants | D15: 12000000 | E15: 12000000
A16: National American Iron & Steel Administrative Set-Aside | D16: 728101 | E16: 500095
A17: CDS | D17: 609255899 | E17: 631659905
A18: CDS Administration | E18: 6116000
A19: Total Appropriation | D19: 1126101000 | E19: 1126101000
A20: Base - set asides: | D20: =D19-SUM(D14:D16) -> 1103040899 | E20: =E19-SUM(E14:E16) -> 1103833905

Sheet overtime
A1: Fiscal Year | B1: # of Projects | C1: Total Earmarked Funds for Project Grants | D1: Available for CWSRF Capitalization Grants | E1: Available for DWSRF Capitalization Grants
A2: 1989 | B2: 4 | C2: 68 | D2: 941 | E2: —
A3: 1990 | B3: 4 | C3: 53 | D3: 967 | E3: —
A4: 1991 | B4: 2 | C4: 36 | D4: 2048 | E4: —
A5: 1992 | B5: 8 | C5: 435 | D5: 1949 | E5: —
A6: 1993 | B6: 13 | C6: 556 | D6: 1928 | E6: —
A7: 1994 | B7: 9 | C7: 558 | D7: 1218 | E7: —
A8: 1995 | B8: 46 | C8: 834 | D8: 1235 | E8: —
A9: 1996 | B9: 20 | C9: 307 | D9: 2074 | E9: —
A10: 1997 | B10: 21 | C10: 301 | D10: 625 | E10: 1275
A11: 1998 | B11: 42 | C11: 393 | D11: 1350 | E11: 725
A12: 1999 | B12: 82 | C12: 402 | D12: 1350 | E12: 775
A13: 2000 | B13: 143 | C13: 395 | D13: 1345 | E13: 820
A14: 2001 | B14: 244 | C14: 466 | D14: 1350 | E14: 825
A15: 2002 | B15: 339 | C15: 459 | D15: 1350 | E15: 850
A16: 2003 | B16: 491 | C16: 413 | D16: 1341 | E16: 845
A17: 2004 | B17: 520 | C17: 425 | D17: 1342 | E17: 845
A18: 2005 | B18: 669 | C18: 402 | D18: 1091 | E18: 843
A19: 2006 | B19: 259 | C19: 289 | D19: 887 | E19: 838
A20: 2007 | B20: 2 | C20: 84 | D20: 1084 | E20: 838
A21: 2008 | B21: 282 | C21: 177 | D21: 689 | E21: 829
... A34: 2021 | B34: 0 | C34: 0 | D34: 1639 | E34: 1126
A35: 2022 | B35: 485 | C35: 841 | D35: 3195 | E35: $6,430‬
A36: 2023 | B36: 715 | C36: 1472 | D36: $3,200‬ | E36: 6519
A37: 2024 | B37: 1035 | C37: 1458
A38: 2025 | B38: 0

Sheet CW_23_cap
A1: state | B1: allotment | C1: pct
A2: Alabama | B2: 8473000 | C2: =B2/tot_allotment!$D$3 -> 0.01118198
A3: Alaska | B3: 4535000 | C3: =B3/tot_allotment!$D$3 -> 0.0059849262
A4: Arizona | B4: 5118000 | C4: =B4/tot_allotment!$D$3 -> 0.0067543224
A5: Arkansas | B5: 4957000 | C5: =B5/tot_allotment!$D$3 -> 0.0065418476
A6: California | B6: 54191000 | C6: =B6/tot_allotment!$D$3 -> 0.071516898
A7: Colorado | B7: 6061000 | C7: =B7/tot_allotment!$D$3 -> 0.0079988175
A8: Connecticut | B8: 9282000 | C8: =B8/tot_allotment!$D$3 -> 0.012249633
A9: Delaware | B9: 3720000 | C9: =B9/tot_allotment!$D$3 -> 0.0049093551
A10: Florida | B10: 25576000 | C10: =B10/tot_allotment!$D$3 -> 0.033753136
A11: Georgia | B11: 12811000 | C11: =B11/tot_allotment!$D$3 -> 0.016906922
A12: Hawaii | B12: 5868000 | C12: =B12/tot_allotment!$D$3 -> 0.0077441117
A13: Idaho | B13: 3720000 | C13: =B13/tot_allotment!$D$3 -> 0.0049093551
... A52: Wyoming | B52: 3720000 | C52: =B52/tot_allotment!$D$3 -> 0.0049093551

Sheet DW_23_cap
A1: state | B1: allotment | C1: pct
A2: Alabama | B2: 8719000 | C2: 0.0177
A3: Alaska | B3: 4938000 | C3: 0.01
A4: Arizona | B4: 8638000 | C4: 0.0175
A5: Arkansas | B5: 5912000 | C5: 0.012
A6: California | B6: 53272000 | C6: 0.1079
A7: Colorado | B7: 8650000 | C7: 0.0175
A8: Connecticut | B8: 4938000 | C8: 0.01
A9: Delaware | B9: 4938000 | C9: 0.01
A10: Florida | B10: 17820000 | C10: 0.0361
A11: Georgia | B11: 13389000 | C11: 0.0271
A12: Hawaii | B12: 4938000 | C12: 0.01
A13: Idaho | B13: 4938000 | C13: 0.01
... A52: Wyoming | B52: 4938000 | C52: 0.01

Sheet cds_23
A1: Agency | B1: Account | C1: State | D1: Project | E1: Amount | F1: House_Requestor | G1: Senate_Requestor | H1: Origination
A2: Environmental Protection Agency | B2: STAG— Drinking Water State Revolving Fund | C2: AK | D2: City of Whittier for Well Field Upgrades | E2: 1230000 | G2: Murkowski | H2: S
A3: Environmental Protection Agency | B3: STAG— Drinking Water State Revolving Fund | C3: AK | D3: Chickaloon Village Traditional Council for Community Well in Chickaloon | E3: 250000 | G3: Murkowski | H3: S
A4: Environmental Protection Agency | B4: STAG— Drinking Water State Revolving Fund | C4: AK | D4: City and Borough of Yakutat for Waterline Extension Project | E4: 5082000 | G4: Murkowski | H4: S
A5: Environmental Protection Agency | B5: STAG— Drinking Water State Revolving Fund | C5: AK | D5: City of Nome for Potable Water Distribution and Wastewater Collection Systems | E5: 1600000 | G5: Murkowski | H5: S
A6: Environmental Protection Agency | B6: STAG— Drinking Water State Revolving Fund | C6: AL | D6: Town of Garden City Water System Im- provements | E6: 520000 | F6: Aderholt | H6: H
A7: Environmental Protection Agency | B7: STAG— Drinking Water State Revolving Fund | C7: AL | D7: Mobile County Water, Sewer, and Fire Pro- tection Authority Water Well Project | E7: 1280000 | F7: Carl | H7: H
A8: Environmental Protection Agency | B8: STAG— Drinking Water State Revolving Fund | C8: AR | D8: Fulton Waterworks for City of Fulton Water System Delivery | E8: 3050000 | G8: Boozman | H8: S
A9: Environmental Protection Agency | B9: STAG— Drinking Water State Revolving Fund | C9: AR | D9: Central Arkansas Water for West Pulaski County Water Delivery | E9: 12000000 | G9: Boozman | H9: S
A10: Environmental Protection Agency | B10: STAG— Drinking Water State Revolving Fund | C10: AZ | D10: Bullhead City for New Drinking Water Well Construction Project | E10: 2000000 | G10: Kelly | H10: S
A11: Environmental Protection Agency | B11: STAG— Drinking Water State Revolving Fund | C11: AZ | D11: Town of Carefree for Silver Saddle Pres- sure Zone Waterline Improvement Project | E11: 800000 | G11: Kelly | H11: S
A12: Environmental Protection Agency | B12: STAG— Drinking Water State Revolving Fund | C12: AZ | D12: City of Page for Water Treatment Plant Ex- pansion Project | E12: 456000 | G12: Kelly | H12: S
A13: Environmental Protection Agency | B13: STAG— Drinking Water State Revolving Fund | C13: AZ | D13: City of Douglas for a Supervisory Control and Data Acquisition System | E13: 833285 | F13: Kirkpatrick | G13: Sinema | H13: H
A14: Environmental Protection Agency | B14: STAG— Drinking Water State Revolving Fund | C14: AZ | D14: Town of Kearny for a Water Infrastructure Project | E14: 3000000 | F14: O’Halleran | H14: H
A15: Environmental Protection Agency | B15: STAG— Drinking Water State Revolving Fund | C15: AZ | D15: Hopi Tribe for a Water Infrastructure Im- provement Project | E15: 1500000 | F15: O’Halleran | G15: Kelly, Sinema | H15: H
A16: Environmental Protection Agency | B16: STAG— Drinking Water State Revolving Fund | C16: AZ | D16: Maricopa-Stanfield Irrigation and Drainage District for the Santa Rosa Canal Project | E16: 2846076 | F16: O’Halleran | G16: Kelly, Sinema | H16: H/S
A17: Environmental Protection Agency | B17: STAG— Drinking Water State Revolving Fund | C17: AZ | D17: City of Page for New Intake Pipes from Lake Powell | E17: 3432000 | F17: O’Halleran | G17: Sinema | H17: H/S
A18: Environmental Protection Agency | B18: STAG— Drinking Water State Revolving Fund | C18: CA | D18: East Palo Alto for East Palo Alto Water In- frastructure Improvements | E18: 800000 | G18: Feinstein | H18: S
A19: Environmental Protection Agency | B19: STAG— Drinking Water State Revolving Fund | C19: CA | D19: County of Tulare for Drinking Water Kiosks | E19: 200000 | G19: Feinstein, Padilla | H19: S
A20: Environmental Protection Agency | B20: STAG— Drinking Water State Revolving Fund | C20: CA | D20: Woodville Public Utility District for Wood- ville PUD Well No. 4 Replacement | E20: 1150000 | G20: Feinstein, Padilla | H20: S
A21: Environmental Protection Agency | B21: STAG— Drinking Water State Revolving Fund | C21: CA | D21: City of Modesto for Grayson Well and Tank Replacement | E21: 1750000 | G21: Feinstein, Padilla | H21: S
A22: Environmental Protection Agency | B22: STAG— Drinking Water State Revolving Fund | C22: CA | D22: Allensworth Community Services District for Allensworth Well Solar Array | E22: 150000 | G22: Feinstein, Padilla | H22: S
A23: Environmental Protection Agency | B23: STAG— Drinking Water State Revolving Fund | C23: CA | D23: City of Tulare for Water Delivery System | E23: 500000 | G23: Feinstein, Padilla | H23: S
A24: Environmental Protection Agency | B24: STAG— Drinking Water State Revolving Fund | C24: CA | D24: City of Dinuba for Well 21 Construction | E24: 1500000 | G24: Padilla | H24: S
A25: Environmental Protection Agency | B25: STAG— Drinking Water State Revolving Fund | C25: CA | D25: Carmichael Water District for Aquifer Stor- age and Recharge Well #2 | E25: 2500000 | F25: Bera | H25: H
A26: Environmental Protection Agency | B26: STAG— Drinking Water State Revolving Fund | C26: CA | D26: Citrus Heights Water District for the High- land Avenue Well Project | E26: 1500000 | F26: Bera | H26: H
A27: Environmental Protection Agency | B27: STAG— Drinking Water State Revolving Fund | C27: CA | D27: Sacramento County for a Regional Con- junctive Use Project | E27: 2800000 | F27: Bera | G27: Padilla | H27: H
A28: Environmental Protection Agency | B28: STAG— Drinking Water State Revolving Fund | C28: CA | D28: City of Oxnard for a Water Pipeline Re- placement | E28: 2846400 | F28: Brownley | G28: Feinstein, Padilla | H28: H
A29: Environmental Protection Agency | B29: STAG— Drinking Water State Revolving Fund | C29: CA | D29: Cachuma Operation and Maintenance Board for the Lake Cachuma Pumping Facility Project | E29: 500000 | F29: Carbajal | G29: Feinstein | H29: H
A30: Environmental Protection Agency | B30: STAG— Drinking Water State Revolving Fund | C30: CA | D30: City of Atwater for the Buhach Road and Gurr Road Utility Extension | E30: 3000000 | F30: Costa | H30: H
A31: Environmental Protection Agency | B31: STAG— Drinking Water State Revolving Fund | C31: CA | D31: Solano Irrigation District for Quail Creek Well Relocation and Associated Convey- ance Facilities | E31: 2824000 | F31: Garamendi | G31: Padilla | H31: H
A32: Environmental Protection Agency | B32: STAG— Drinking Water State Revolving Fund | C32: CA | D32: City of Ripon for the SSJID Surface Water Connection Project | E32: 3452972 | F32: Harder (CA) | H32: H
A33: Environmental Protection Agency | B33: STAG— Drinking Water State Revolving Fund | C33: CA | D33: Stanislaus County for a Crows Landing Water Wells Project | E33: 3452972 | F33: Harder (CA) | G33: Padilla | H33: H
A34: Environmental Protection Agency | B34: STAG— Drinking Water State Revolving Fund | C34: CA | D34: Valley Center Municipal Water District Lilac Road Pipeline Replacement Project | E34: 3060000 | F34: Issa | G34: Feinstein, Padilla | H34: H
A35: Environmental Protection Agency | B35: STAG— Drinking Water State Revolving Fund | C35: CA | D35: Borrego Water District—Borrego Spring Road Transmission Main and Sun Gold Pipeline Replacement Projects | E35: 3392667 | F35: Issa | G35: Padilla | H35: H
A36: Environmental Protection Agency | B36: STAG— Drinking Water State Revolving Fund | C36: CA | D36: Orange County Water District PFAS Groundwater Treatment Project | E36: 5000000 | F36: Kim (CA) | G36: Padilla | H36: H
A37: Environmental Protection Agency | B37: STAG— Drinking Water State Revolving Fund | C37: CA | D37: Placer County Water Agency Alta Loop Pipeline Project | E37: 1000000 | F37: LaMalfa | H37: H
A38: Environmental Protection Agency | B38: STAG— Drinking Water State Revolving Fund | C38: CA | D38: City of Sacramento for the Shasta Ground- water Well Project | E38: 3452972 | F38: Matsui | H38: H
A39: Environmental Protection Agency | B39: STAG— Drinking Water State Revolving Fund | C39: CA | D39: City of Azusa for Aspan Well Treatment and Rehabilitation | E39: 2500000 | F39: Napolitano | H39: H
A40: Environmental Protection Agency | B40: STAG— Drinking Water State Revolving Fund | C40: CA | D40: City of Salinas for the Castroville Seawater Intrusion Project | E40: 900000 | F40: Panetta | G40: Feinstein, Padilla | H40: H
...

Sheet Sheet1
A1: Agency | B1: Account | C1: State | D1: Project | E1: Amount | F1: House_Requestor | G1: Senate_Requestor | H1: Origination | J1: Sum of Amount | K1: Column Labels
A2: Environmental Protection Agency | B2: STAG— Drinking Water State Revolving Fund | C2: AK | D2: City of Whittier for Well Field Upgrades | E2: 1230000 | G2: Murkowski | H2: S | J2: Row Labels | K2: STAG— Drinking Water State Revolving Fund | L2: STAG—Clean Water State Revolving Fund | M2: (blank) | N2: Grand Total
A3: Environmental Protection Agency | B3: STAG— Drinking Water State Revolving Fund | C3: AK | D3: Chickaloon Village Traditional Council for Community Well in Chickaloon | E3: 250000 | G3: Murkowski | H3: S | J3: AK | K3: 8162000 | L3: 55520000 | N3: 63682000
A4: Environmental Protection Agency | B4: STAG— Drinking Water State Revolving Fund | C4: AK | D4: City and Borough of Yakutat for Waterline Extension Project | E4: 5082000 | G4: Murkowski | H4: S | J4: AL | K4: 1800000 | L4: 7000000 | N4: 8800000
A5: Environmental Protection Agency | B5: STAG— Drinking Water State Revolving Fund | C5: AK | D5: City of Nome for Potable Water Distribution and Wastewater Collection Systems | E5: 1600000 | G5: Murkowski | H5: S | J5: AR | K5: 15050000 | L5: 4660000 | N5: 19710000
A6: Environmental Protection Agency | B6: STAG— Drinking Water State Revolving Fund | C6: AL | D6: Town of Garden City Water System Im- provements | E6: 520000 | F6: Aderholt | H6: H | J6: AZ | K6: 14867361 | L6: 12602350 | N6: 27469711
A7: Environmental Protection Agency | B7: STAG— Drinking Water State Revolving Fund | C7: AL | D7: Mobile County Water, Sewer, and Fire Pro- tection Authority Water Well Project | E7: 1280000 | F7: Carl | H7: H | J7: CA | K7: 74512099 | L7: 74948832 | N7: 149460931
A8: Environmental Protection Agency | B8: STAG— Drinking Water State Revolving Fund | C8: AR | D8: Fulton Waterworks for City of Fulton Water System Delivery | E8: 3050000 | G8: Boozman | H8: S | J8: CNMI | L8: 911302 | N8: 911302
A9: Environmental Protection Agency | B9: STAG— Drinking Water State Revolving Fund | C9: AR | D9: Central Arkansas Water for West Pulaski County Water Delivery | E9: 12000000 | G9: Boozman | H9: S | J9: CO | K9: 13193600 | L9: 2454000 | N9: 15647600
A10: Environmental Protection Agency | B10: STAG— Drinking Water State Revolving Fund | C10: AZ | D10: Bullhead City for New Drinking Water Well Construction Project | E10: 2000000 | G10: Kelly | H10: S | J10: CT | K10: 7863000 | L10: 9225000 | N10: 17088000
A11: Environmental Protection Agency | B11: STAG— Drinking Water State Revolving Fund | C11: AZ | D11: Town of Carefree for Silver Saddle Pres- sure Zone Waterline Improvement Project | E11: 800000 | G11: Kelly | H11: S | J11: DE | K11: 1800000 | L11: 10560000 | N11: 12360000
A12: Environmental Protection Agency | B12: STAG— Drinking Water State Revolving Fund | C12: AZ | D12: City of Page for Water Treatment Plant Ex- pansion Project | E12: 456000 | G12: Kelly | H12: S | J12: FL | K12: 12692972 | L12: 51772327 | N12: 64465299
A13: Environmental Protection Agency | B13: STAG— Drinking Water State Revolving Fund | C13: AZ | D13: City of Douglas for a Supervisory Control and Data Acquisition System | E13: 833285 | F13: Kirkpatrick | G13: Sinema | H13: H | J13: GA | K13: 6436000 | L13: 29398290 | N13: 35834290
A14: Environmental Protection Agency | B14: STAG— Drinking Water State Revolving Fund | C14: AZ | D14: Town of Kearny for a Water Infrastructure Project | E14: 3000000 | F14: O’Halleran | H14: H | J14: HI | K14: 2160000 | L14: 4199000 | N14: 6359000
A15: Environmental Protection Agency | B15: STAG— Drinking Water State Revolving Fund | C15: AZ | D15: Hopi Tribe for a Water Infrastructure Im- provement Project | E15: 1500000 | F15: O’Halleran | G15: Kelly, Sinema | H15: H | J15: IA | L15: 6000000 | N15: 6000000
A16: Environmental Protection Agency | B16: STAG— Drinking Water State Revolving Fund | C16: AZ | D16: Maricopa-Stanfield Irrigation and Drainage District for the Santa Rosa Canal Project | E16: 2846076 | F16: O’Halleran | G16: Kelly, Sinema | H16: H/S | J16: ID | L16: 4560000 | N16: 4560000
A17: Environmental Protection Agency | B17: STAG— Drinking Water State Revolving Fund | C17: AZ | D17: City of Page for New Intake Pipes from Lake Powell | E17: 3432000 | F17: O’Halleran | G17: Sinema | H17: H/S | J17: IL | K17: 25470095 | L17: 22548296 | N17: 48018391
A18: Environmental Protection Agency | B18: STAG— Drinking Water State Revolving Fund | C18: CA | D18: East Palo Alto for East Palo Alto Water In- frastructure Improvements | E18: 800000 | G18: Feinstein | H18: S | J18: KS | K18: 10000000 | L18: 21100000 | N18: 31100000
A19: Environmental Protection Agency | B19: STAG— Drinking Water State Revolving Fund | C19: CA | D19: County of Tulare for Drinking Water Kiosks | E19: 200000 | G19: Feinstein, Padilla | H19: S | J19: KY | K19: 11328000 | L19: 12899000 | N19: 24227000
A20: Environmental Protection Agency | B20: STAG— Drinking Water State Revolving Fund | C20: CA | D20: Woodville Public Utility District for Wood- ville PUD Well No. 4 Replacement | E20: 1150000 | G20: Feinstein, Padilla | H20: S | J20: LA | K20: 4430000 | L20: 10000000 | N20: 14430000
A21: Environmental Protection Agency | B21: STAG— Drinking Water State Revolving Fund | C21: CA | D21: City of Modesto for Grayson Well and Tank Replacement | E21: 1750000 | G21: Feinstein, Padilla | H21: S | J21: MA | K21: 14600894 | L21: 19765800 | N21: 34366694
A22: Environmental Protection Agency | B22: STAG— Drinking Water State Revolving Fund | C22: CA | D22: Allensworth Community Services District for Allensworth Well Solar Array | E22: 150000 | G22: Feinstein, Padilla | H22: S | J22: MD | K22: 5845000 | L22: 10818972 | N22: 16663972
A23: Environmental Protection Agency | B23: STAG— Drinking Water State Revolving Fund | C23: CA | D23: City of Tulare for Water Delivery System | E23: 500000 | G23: Feinstein, Padilla | H23: S | J23: ME | K23: 6084000 | L23: 25829453 | N23: 31913453
A24: Environmental Protection Agency | B24: STAG— Drinking Water State Revolving Fund | C24: CA | D24: City of Dinuba for Well 21 Construction | E24: 1500000 | G24: Padilla | H24: S | J24: MI | K24: 25796772 | L24: 32925944 | N24: 58722716
A25: Environmental Protection Agency | B25: STAG— Drinking Water State Revolving Fund | C25: CA | D25: Carmichael Water District for Aquifer Stor- age and Recharge Well #2 | E25: 2500000 | F25: Bera | H25: H | J25: MN | K25: 17572972 | L25: 12380000 | N25: 29952972
A26: Environmental Protection Agency | B26: STAG— Drinking Water State Revolving Fund | C26: CA | D26: Citrus Heights Water District for the High- land Avenue Well Project | E26: 1500000 | F26: Bera | H26: H | J26: MO | K26: 22240000 | L26: 17401027 | N26: 39641027
A27: Environmental Protection Agency | B27: STAG— Drinking Water State Revolving Fund | C27: CA | D27: Sacramento County for a Regional Con- junctive Use Project | E27: 2800000 | F27: Bera | G27: Padilla | H27: H | J27: MS | K27: 18626424 | L27: 23000000 | N27: 41626424
A28: Environmental Protection Agency | B28: STAG— Drinking Water State Revolving Fund | C28: CA | D28: City of Oxnard for a Water Pipeline Re- placement | E28: 2846400 | F28: Brownley | G28: Feinstein, Padilla | H28: H | J28: NC | K28: 9046872 | L28: 17285839 | N28: 26332711
A29: Environmental Protection Agency | B29: STAG— Drinking Water State Revolving Fund | C29: CA | D29: Cachuma Operation and Maintenance Board for the Lake Cachuma Pumping Facility Project | E29: 500000 | F29: Carbajal | G29: Feinstein | H29: H | J29: NH | K29: 6452972 | L29: 9935000 | N29: 16387972
A30: Environmental Protection Agency | B30: STAG— Drinking Water State Revolving Fund | C30: CA | D30: City of Atwater for the Buhach Road and Gurr Road Utility Extension | E30: 3000000 | F30: Costa | H30: H | J30: NJ | K30: 30896395 | L30: 28126818 | N30: 59023213
A31: Environmental Protection Agency | B31: STAG— Drinking Water State Revolving Fund | C31: CA | D31: Solano Irrigation District for Quail Creek Well Relocation and Associated Convey- ance Facilities | E31: 2824000 | F31: Garamendi | G31: Padilla | H31: H | J31: NM | K31: 4065000 | L31: 13952000 | N31: 18017000
A32: Environmental Protection Agency | B32: STAG— Drinking Water State Revolving Fund | C32: CA | D32: City of Ripon for the SSJID Surface Water Connection Project | E32: 3452972 | F32: Harder (CA) | H32: H | J32: NV | K32: 16106640 | L32: 18269600 | N32: 34376240
A33: Environmental Protection Agency | B33: STAG— Drinking Water State Revolving Fund | C33: CA | D33: Stanislaus County for a Crows Landing Water Wells Project | E33: 3452972 | F33: Harder (CA) | G33: Padilla | H33: H | J33: NY | K33: 46517616 | L33: 63646193 | N33: 110163809
A34: Environmental Protection Agency | B34: STAG— Drinking Water State Revolving Fund | C34: CA | D34: Valley Center Municipal Water District Lilac Road Pipeline Replacement Project | E34: 3060000 | F34: Issa | G34: Feinstein, Padilla | H34: H | J34: OH | K34: 11428540 | L34: 36334946 | N34: 47763486
A35: Environmental Protection Agency | B35: STAG— Drinking Water State Revolving Fund | C35: CA | D35: Borrego Water District—Borrego Spring Road Transmission Main and Sun Gold Pipeline Replacement Projects | E35: 3392667 | F35: Issa | G35: Padilla | H35: H | J35: OK | K35: 32203281 | L35: 10936000 | N35: 43139281
A36: Environmental Protection Agency | B36: STAG— Drinking Water State Revolving Fund | C36: CA | D36: Orange County Water District PFAS Groundwater Treatment Project | E36: 5000000 | F36: Kim (CA) | G36: Padilla | H36: H | J36: OR | K36: 20522000 | L36: 15952950 | N36: 36474950
A37: Environmental Protection Agency | B37: STAG— Drinking Water State Revolving Fund | C37: CA | D37: Placer County Water Agency Alta Loop Pipeline Project | E37: 1000000 | F37: LaMalfa | H37: H | J37: PA | K37: 5040400 | L37: 28517287 | N37: 33557687
A38: Environmental Protection Agency | B38: STAG— Drinking Water State Revolving Fund | C38: CA | D38: City of Sacramento for the Shasta Ground- water Well Project | E38: 3452972 | F38: Matsui | H38: H | J38: RI | K38: 5000000 | L38: 10828000 | N38: 15828000
A39: Environmental Protection Agency | B39: STAG— Drinking Water State Revolving Fund | C39: CA | D39: City of Azusa for Aspan Well Treatment and Rehabilitation | E39: 2500000 | F39: Napolitano | H39: H | J39: SC | K39: 9900000 | L39: 19523000 | N39: 29423000
A40: Environmental Protection Agency | B40: STAG— Drinking Water State Revolving Fund | C40: CA | D40: City of Salinas for the Castroville Seawater Intrusion Project | E40: 900000 | F40: Panetta | G40: Feinstein, Padilla | H40: H | J40: TN | K40: 5800000 | L40: 4122800 | N40: 9922800
...

Sheet CW_24_cap
A1: state | B1: allotment | C1: pct
A2: Alabama | B2: 9221000 | C2: =B2/tot_allotment!$E$3 -> 0.011181795
A3: Alaska | B3: 4935000 | C3: =B3/tot_allotment!$E$3 -> 0.0059844005
A4: Arizona | B4: 5570000 | C4: =B4/tot_allotment!$E$3 -> 0.0067544298
A5: Arkansas | B5: 5394000 | C5: =B5/tot_allotment!$E$3 -> 0.0065410044
A6: California | B6: 58976000 | C6: =B6/tot_allotment!$E$3 -> 0.071516921
A7: Colorado | B7: 6596000 | C7: =B7/tot_allotment!$E$3 -> 0.007998603
A8: Connecticut | B8: 10102000 | C8: =B8/tot_allotment!$E$3 -> 0.012250135
A9: Delaware | B9: 4048000 | C9: =B9/tot_allotment!$E$3 -> 0.0049087849
A10: Florida | B10: 27835000 | C10: =B10/tot_allotment!$E$3 -> 0.033753959
A11: Georgia | B11: 13942000 | C11: =B11/tot_allotment!$E$3 -> 0.016906689
A12: Hawaii | B12: 6387000 | C12: =B12/tot_allotment!$E$3 -> 0.0077451603
A13: Idaho | B13: 4048000 | C13: =B13/tot_allotment!$E$3 -> 0.0049087849
... A52: Wyoming | B52: 4048000 | C52: =B52/tot_allotment!$E$3 -> 0.0049087849

Sheet DW_24_cap
A1: state | B1: allotment | C1: pct
A2: Alabama | B2: 8229000 | C2: 0.0177
A3: Alaska | B3: 4661000 | C3: 0.01
A4: Arizona | B4: 8153000 | C4: 0.0175
A5: Arkansas | B5: 5580000 | C5: 0.012
A6: California | B6: 50283000 | C6: 0.1079
A7: Colorado | B7: 8164000 | C7: 0.0175
A8: Connecticut | B8: 4661000 | C8: 0.01
A9: Delaware | B9: 4661000 | C9: 0.01
A10: Florida | B10: 16819000 | C10: 0.0361
A11: Georgia | B11: 12637000 | C11: 0.0271
A12: Hawaii | B12: 4661000 | C12: 0.01
A13: Idaho | B13: 4661000 | C13: 0.01
... A52: Wyoming | B52: 4661000 | C52: 0.01

Sheet cds_24
A1: Agency | B1: Account | C1: State | D1: Project | E1: Amount | F1: House_Requestor | G1: Senate_Requestor | H1: Origination
A2: Environmental Protection Agency | B2: STAG—Clean Water State Revolving Fund | C2: AL | D2: City of Cullman for Sanitary Sewer Im- provements | E2: 4250000 | F2: Aderholt | H2: H
A3: Environmental Protection Agency | B3: STAG—Clean Water State Revolving Fund | C3: AL | D3: City of Priceville for Sanitary Sewer Im- provements | E3: 1750000 | F3: Strong | H3: H
A4: Environmental Protection Agency | B4: STAG—Clean Water State Revolving Fund | C4: AZ | D4: City of Tempe for Recharge Wells Pipelines | E4: 959752 | F4: Stanton | G4: Sinema | H4: H
A5: Environmental Protection Agency | B5: STAG—Clean Water State Revolving Fund | C5: AZ | D5: City of Tolleson for Wastewater Digester Rehabilitation Project | E5: 959752 | F5: Gallego | G5: Sinema | H5: H
A6: Environmental Protection Agency | B6: STAG—Clean Water State Revolving Fund | C6: AZ | D6: Tucson Water for Water Recharge Expan- sion Project | E6: 1250000 | F6: Ciscomani | G6: Sinema | H6: H
A7: Environmental Protection Agency | B7: STAG—Clean Water State Revolving Fund | C7: CA | D7: Arvin-Edison Water Storage District for Water Pipeline Project | E7: 3250000 | F7: Valadao | H7: H
A8: Environmental Protection Agency | B8: STAG—Clean Water State Revolving Fund | C8: CA | D8: Big Bear Area Regional Wastewater Agency for Water Reuse Project | E8: 1000000 | F8: Obernolte | G8: Padilla | H8: H
A9: Environmental Protection Agency | B9: STAG—Clean Water State Revolving Fund | C9: CA | D9: California Department of Parks and Recre- ation, Angeles Division for Taylor Yard Stormwater Project | E9: 959752 | F9: Gomez | H9: H
A10: Environmental Protection Agency | B10: STAG—Clean Water State Revolving Fund | C10: CA | D10: City of Adelanto for Water and Wastewater Infrastructure Improvements | E10: 750000 | F10: Obernolte | H10: H
A11: Environmental Protection Agency | B11: STAG—Clean Water State Revolving Fund | C11: CA | D11: City of Compton for Pearl Avenue Sewer Replacement Project | E11: 959752 | F11: Waters | G11: Feinstein, Padilla | H11: H
A12: Environmental Protection Agency | B12: STAG—Clean Water State Revolving Fund | C12: CA | D12: City of Daly City for Vista Grande Drainage Basin Improvement Project | E12: 959752 | F12: Mullin | H12: H
A13: Environmental Protection Agency | B13: STAG—Clean Water State Revolving Fund | C13: CA | D13: City of Del Mar for Stormwater and Sewer Infrastructure Improvement Project | E13: 959752 | F13: Levin | G13: Padilla | H13: H
A14: Environmental Protection Agency | B14: STAG—Clean Water State Revolving Fund | C14: CA | D14: City of Dinuba for Sewer Improvements | E14: 959752 | F14: Costa | G14: Padilla | H14: H
A15: Environmental Protection Agency | B15: STAG—Clean Water State Revolving Fund | C15: CA | D15: City of Madera for Sewer Trunk Main Project | E15: 1000000 | F15: Duarte | H15: H
A16: Environmental Protection Agency | B16: STAG—Clean Water State Revolving Fund | C16: CA | D16: City of Madera for Storm Drain Pipeline Replacement | E16: 1000000 | F16: Duarte | G16: Padilla | H16: H
A17: Environmental Protection Agency | B17: STAG—Clean Water State Revolving Fund | C17: CA | D17: City of Oakland for Lake Merritt Healthy Lake Initiative | E17: 959757 | F17: Lee (CA) | G17: Feinstein, Padilla | H17: H
A18: Environmental Protection Agency | B18: STAG—Clean Water State Revolving Fund | C18: CA | D18: City of Pleasanton for South Livermore Sewer Expansion Project | E18: 959752 | F18: Swalwell | H18: H
A19: Environmental Protection Agency | B19: STAG—Clean Water State Revolving Fund | C19: CA | D19: City of Rio Vista for Reclaimed Water Sys- tem Completion Project (Purple Piping) | E19: 959752 | F19: Thompson (CA) | H19: H
A20: Environmental Protection Agency | B20: STAG—Clean Water State Revolving Fund | C20: CA | D20: City of Salinas for Wastewater Treatment Facility Project | E20: 959752 | F20: Lofgren | G20: Padilla | H20: H
A21: Environmental Protection Agency | B21: STAG—Clean Water State Revolving Fund | C21: CA | D21: City of San Diego for Harbor Drive Pump Station 1 and 2 Project | E21: 959752 | F21: Peters | H21: H
A22: Environmental Protection Agency | B22: STAG—Clean Water State Revolving Fund | C22: CA | D22: City of Santa Maria for Storm Drainage Improvements Project | E22: 959752 | F22: Carbajal | G22: Feinstein, Padilla | H22: H
A23: Environmental Protection Agency | B23: STAG—Clean Water State Revolving Fund | C23: CA | D23: City of Stockton for Diamond Sewer Upsizing Project | E23: 959757 | F23: Harder | H23: H
A24: Environmental Protection Agency | B24: STAG—Clean Water State Revolving Fund | C24: CA | D24: City of Thousand Oaks for Stormwater Capture and Diversion Project | E24: 959752 | F24: Brownley | H24: H
A25: Environmental Protection Agency | B25: STAG—Clean Water State Revolving Fund | C25: CA | D25: City of Tulare for Traver Sewer Project | E25: 750000 | F25: Costa | H25: H
A26: Environmental Protection Agency | B26: STAG—Clean Water State Revolving Fund | C26: CA | D26: City of Turlock for Sewer Extension Project | E26: 1200000 | F26: Duarte | G26: Padilla | H26: H
A27: Environmental Protection Agency | B27: STAG—Clean Water State Revolving Fund | C27: CA | D27: City of Turlock for Stormwater Infrastruc- ture | E27: 1000000 | F27: Duarte | G27: Feinstein, Padilla | H27: H
A28: Environmental Protection Agency | B28: STAG—Clean Water State Revolving Fund | C28: CA | D28: City of Twentynine Palms for Wastewater Improvements | E28: 1000000 | F28: Obernolte | G28: Feinstein, Padilla | H28: H
A29: Environmental Protection Agency | B29: STAG—Clean Water State Revolving Fund | C29: CA | D29: City of Watsonville for Wastewater Treat- ment Facility | E29: 959752 | F29: Lofgren | H29: H
A30: Environmental Protection Agency | B30: STAG—Clean Water State Revolving Fund | C30: CA | D30: City of Yucaipa for Stormwater Infrastruc- ture Project | E30: 1750000 | F30: Obernolte | G30: Padilla | H30: H
A31: Environmental Protection Agency | B31: STAG—Clean Water State Revolving Fund | C31: CA | D31: County of Los Angeles for Rio Hondo Res- toration Project | E31: 959752 | F31: Chu | H31: H
A32: Environmental Protection Agency | B32: STAG—Clean Water State Revolving Fund | C32: CA | D32: County of Orange for Poche Beach Water Reclamation Project | E32: 959752 | F32: Levin | H32: H
A33: Environmental Protection Agency | B33: STAG—Clean Water State Revolving Fund | C33: CA | D33: Culver City for Stormwater Diversion | E33: 959752 | F33: Lieu | H33: H
A34: Environmental Protection Agency | B34: STAG—Clean Water State Revolving Fund | C34: CA | D34: Eastern Municipal Water District for Puri- fied Water Replenishment Project | E34: 959752 | F34: Takano | H34: H
A35: Environmental Protection Agency | B35: STAG—Clean Water State Revolving Fund | C35: CA | D35: Eastern Municipal Water District for Recy- cled Water Pipeline Construction | E35: 638540 | F35: Issa | H35: H
A36: Environmental Protection Agency | B36: STAG—Clean Water State Revolving Fund | C36: CA | D36: Goleta County for Wastewater Reuse Project | E36: 773870 | F36: Carbajal | H36: H
A37: Environmental Protection Agency | B37: STAG—Clean Water State Revolving Fund | C37: CA | D37: Los Angeles County Public Works for Stormwater Infrastructure Improvements | E37: 1050000 | F37: Garcia, Mike (CA) | H37: H
A38: Environmental Protection Agency | B38: STAG—Clean Water State Revolving Fund | C38: CA | D38: Mojave Water Agency for Stormwater Cap- ture and Recharge | E38: 1750000 | F38: Obernolte | G38: Feinstein, Padilla | H38: H
A39: Environmental Protection Agency | B39: STAG—Clean Water State Revolving Fund | C39: CA | D39: Pittsburg Power Company for Water Treat- ment Plant Fuel Cell Project | E39: 959752 | F39: Garamendi | H39: H
A40: Environmental Protection Agency | B40: STAG—Clean Water State Revolving Fund | C40: CA | D40: Port of Redwood City for Storm Water and Clean Water Improvement | E40: 700000 | F40: Mullin | G40: Feinstein, Padilla | H40: H
...

Sheet dwsrf_tracker
A1: community_served | B1: borrower | C1: pwsid | D1: project_id | E1: project_name | F1: project_type | G1: project_cost | H1: requested_amount | I1: funding_amount | J1: principal_forgiveness | K1: population | L1: project_description | M1: disadvantaged | N1: project_rank | O1: project_score | P1: expecting_funding | Q1: state | R1: state_fiscal_year
A2: Marion | B2: Fairview, Town of | C2: NA | D2: NA | E2: Phase I-Connection to Monumental PSD | F2: General | G2: 3179430 | H2: 2179430 | I2: 466000 | J2: 233000 | K2: 979 | L2: This preliminary application is to make improvements the Town of Fairview‚Äôs water distribution system and to connect to the Monumental PSD‚Äôs water system. The project will be split into two (2) phases. This application is for Phase I. Phase I will primarily consist of the installation of approximately 3,500 LF of 6"" water line, a PRV Station, a duplex booster station with telemetry and emergency generator, refurbish existing water storage tank, upgrade access roads to existing water storage tanks, upgrade telemetry to existing water storage tanks, demolish old tank at water treatment plant, decommission existing water treatment plant, a new office building, | M2: Yes | N2: 1 | O2: 100 | P2: Yes | Q2: West Virginia | R2: 2023
A3: Wyoming | B3: Pineville Municipal Waterworks | C3: NA | D3: NA | E3: Brenton/Baileysville Waterline Extensions | F3: General | G3: 9498871 | H3: 1912371 | I3: 2912371 | J3: 1000000 | K3: 2945 | L3: The proposed project consists of a new 8-inch line that will extend along WV Route 97 to Baileysville Elementary School from the end of the existing 8-inch line near Wyoming. Also there will be 6-inch lines extending from Route 97 along Lanes Branch Road and Doublecamp Branch Road for approximately 0.53 miles and 0.94 miles, respectively. This alternative will also feature one 150,000-gallon water storage tank | M3: Yes | N3: 2 | O3: 100 | P3: Yes | Q3: West Virginia | R3: 2023
A4: Hardy | B4: Wardensville, Town of | C4: NA | D4: NA | E4: Water System Improvements | F4: General | G4: 2421000 | H4: 3124477 | I4: 3421000 | J4: 1000000 | K4: 788 | L4: This project is to replace the fire hydrants and water meters in the distribution system; replace the Warden Acres water storage tank with a 330,000 gallon tank and the Anderson Ridge water storage tank with a 304,000 gallon tank: drill a new water well at the Town of Wardensville water treatment plant site; add a SCADA system; and upgrade/rehabilitate the existing Town of Wardensville‚Äôs water treatment plant with major work to consist of upgrade the electrical service, upgrade the chlorine room, upgrade mechanical piping, and add a generator. | M4: Yes | N4: 3 | O4: 90 | P4: Yes | Q4: West Virginia | R4: 2023
A5: Marion | B5: Fairview, Town of | C5: NA | D5: NA | E5: Phase II-Water line Replacements | F5: General | G5: 2175000 | H5: 1175000 | I5: 344000 | J5: 172000 | K5: 979 | L5: This project will replace 11,000 ft of old water mains, install 14 new valves and 5 fire hydrants in order to reduce significant water loss. | M5: Yes | N5: 4 | O5: 90 | P5: Yes | Q5: West Virginia | R5: 2023
A6: Harrison | B6: Salem, City of | C6: NA | D6: NA | E6: Phase IV Water System Improvements | F6: General | G6: 3500000 | H6: 2400000 | I6: No Information | J6: No Information | K6: 1617 | L6: The City of Salem is proposing to replace approximately 1.5 miles (8,000 LF) of problematic 8-inch water main, along with short sections of 6-inch connection lines, utility service lines (including lead and galvanized) and 128 water meters. Two short sections of 2-inch water line will also be replaced and a leak detection will be performed on the rest of the distribution system. | M6: Yes | N6: 5 | O6: 90 | P6: No | Q6: West Virginia | R6: 2023
A7: McDowell | B7: McDowell County PSD | C7: NA | D7: NA | E7: Elkhorn Ph III | F7: General | G7: 7513000 | H7: 856500 | I7: 1713000 | J7: 856500 | K7: 693 | L7: The proposed project will construct a new water treatment plant to serve 220 customers and will allow 3 old treatment plants (Greenbrier, Ashland, and Crumpler) to be retired in the area. Also included in the project will be a 50 GPM booster station, (2) 100,000-gallon water storage tanks, approximately 60,645 linear feet of 8- inch and smaller waterline, 24 fire hydrants, and all other necessary valves and appurtenances. | M7: Yes | N7: 6 | O7: 80 | P7: Yes | Q7: West Virginia | R7: 2023
A8: Pendleton | B8: Town of Franklin | C8: NA | D8: NA | E8: Plant Upgrade/Line Replacement | F8: General | G8: 3472318 | H8: 1300000 | I8: 2772318 | J8: 500000 | K8: 1702 | L8: The proposed project consists of: 8‚Äù directional drill river crossing, upgrades at the Hanover Storage Tank, replacement of the altitude valve, and upgrades to the Morton Storage Tank. At the water treatment plant work includes; upgrade secondary water source, replace backwash pump, upgrade backwash tank, upgrade plant instrumentation, upgrade plant building, and upgrade sediment basin, Installation of two 40,000 gallon clear well tanks, new automation, VFD‚Äôs on pump motors, new automatic transfer switch, and replace the plant emergency generator. | M8: Yes | N8: 7 | O8: 80 | P8: Yes | Q8: West Virginia | R8: 2023
A9: Barbour | B9: Chestnut Ridge PSD | C9: NA | D9: NA | E9: Water System Improvements | F9: General | G9: 5300000 | H9: 500000 | I9: 1902500 | J9: No Information | K9: 2643 | L9: This project will make improvements to the PSD's water distribution system, including water line and valve replacement, upgrading booster stations, replacing water meters and upgrades to the SCADA and telemetry systems. | M9: Yes | N9: 8 | O9: 80 | P9: Yes | Q9: West Virginia | R9: 2023
A10: Mercer | B10: Mercer County PSD | C10: NA | D10: NA | E10: Water System Improvements | F10: General | G10: 2698000 | H10: 2698000 | I10: No Information | J10: No Information | K10: No Information | L10: This project will extend the water system to the McComas area and replace the existing failing McComas water system. | M10: No Information | N10: 9 | O10: 75 | P10: No | Q10: West Virginia | R10: 2023
A11: Morgan | B11: Paw Paw, Town of | C11: NA | D11: NA | E11: Water System Improvements | F11: General | G11: 4395600 | H11: 3395600 | I11: No Information | J11: No Information | K11: 488 | L11: This Preliminary Application is to upgrade the Town of Paw Paw water treatment plant and distribution system. The distribution portion of the project will consist of the installation of approximately 2 miles (10,780 LF) of 2"" to 8‚Äù water line; and rehabilitate the existing water storage tanks. | M11: Yes | N11: 10 | O11: 70 | P11: No | Q11: West Virginia | R11: 2023
A12: Nicholas | B12: Richwood, City of | C12: NA | D12: NA | E12: Surface Water Intake Impound Structure Project | F12: General | G12: 2000000 | H12: 1000000 | I12: 900000 | J12: 200000 | K12: 1095 | L12: The proposed project will replace the raw water intake impoundment that helps to regulate the water level around the water treatment plant‚Äôs raw water intake. Included in this project will be building a new surface water intake impound structure, demolition and removal of the existing impound infrastructure, installation of a catwalk with manual gate, construction of a new intake screening structure, approximately 200 LF of 12‚Äù mains, 300 LF of 2‚Äù air line and site electric with equipment for an air compressor building, and various reclamation of disturbed areas. | M12: Yes | N12: 11 | O12: 70 | P12: Yes | Q12: West Virginia | R12: 2023
A13: Ritchie | B13: Pennsboro, City of | C13: NA | D13: NA | E13: Water System Improvements | F13: General | G13: 2112000 | H13: 500000 | I13: 1000000 | J13: 500000 | K13: 1291 | L13: The proposed project plans to replace the existing 434,000 gallon Industrial Park Tank with a new like-sized tank and to rehabilitate the Park Drive and Broadwater Water Storage Tanks. Also included will be the replacement of almost 1.14 miles of mostly 8-inch watermains with a small portion being 2-inch and 6-inch. All necessary valves and appurtenances will be included as well as the demolition and site preparation for the new tank. | M13: Yes | N13: 12 | O13: 70 | P13: Yes | Q13: West Virginia | R13: 2023
A14: Greenbrier | B14: Alderson, Town of | C14: NA | D14: NA | E14: Water System Rehab & Expansion | F14: General | G14: 9013000 | H14: 5398000 | I14: 7360258 | J14: 2699000 | K14: 2458 | L14: This preliminary application is for the Town of Alderson to extend water service to the Riverside Rest area and to repair/replace various parts of the water distribution system and water treatment facilities. | M14: Yes | N14: 13 | O14: 70 | P14: Yes | Q14: West Virginia | R14: 2023
A15: Wyoming | B15: Town of Oceana | C15: NA | D15: NA | E15: Water System Upgrade Phase II | F15: General | G15: 5000000 | H15: 3000000 | I15: 1905076 | J15: 952538 | K15: 3797 | L15: Phase 2 of a water system upgrade project for the Town of Oceana and the surrounding area. Project includes replacing Lynco water storage tank, water plant upgrades, telemetry upgrades, replacing water meters, booster station upgrades, and upgrading existing water lines along Rt 10, Rt 85, Popular St. and Chestnut St. | M15: Yes | N15: 14 | O15: 70 | P15: Yes | Q15: West Virginia | R15: 2023
A16: McDowell | B16: Gary, City of | C16: NA | D16: NA | E16: Water System Improvements | F16: General | G16: 3587000 | H16: 500000 | I16: No Information | J16: No Information | K16: 1633 | L16: The project includes the engineering services necessary to conduct a feasibility study that will review alternate water sources for the city's water distribution system. Including alternative raw water sources, emergency interconnect to the City of Welch, emergency interconnect to the McDowell County PSD and consolidation with a nearby water utility. | M16: Yes | N16: 15 | O16: 65 | P16: No | Q16: West Virginia | R16: 2023
A17: Lincoln | B17: Lincoln PSD | C17: NA | D17: NA | E17: Alum Creek Water Storage Tank Replacement | F17: General | G17: 1000000 | H17: 250000 | I17: 500000 | J17: 250000 | K17: 2473 | L17: This project will replace the Lincoln PSD‚Äôs Alum Creek Water Storage Tank with a new 300,000 gallon tank. | M17: Yes | N17: 16 | O17: 65 | P17: Yes | Q17: West Virginia | R17: 2023
A18: Ritchie | B18: Cairo, Town of | C18: NA | D18: NA | E18: Water System Improvements | F18: General | G18: 4000000 | H18: 1000000 | I18: 1000000 | J18: 500000 | K18: 406 | L18: This project will make improvements to the Town of Cairo water distribution system. The project will consist of the 190 new water meters, replacement of 20 valves, replace the existing PRV station, clean and refurbish the existing 214,000 gallon storage tank, replace a river crossing; stabilize a river bank, replace 12 fire hydrants, install 12 fire hydrants, replace approximately 2.5 miles (13,400 LF) of 6"" and 2"" water line, and replace approximately 1.1 miles (6,000 LF) of 3/4"" water line. | M18: Yes | N18: 17 | O18: 65 | P18: Yes | Q18: West Virginia | R18: 2023
A19: Marion | B19: Town of Worthington | C19: NA | D19: NA | E19: Worthington Line Upgrades/Replacement | F19: General | G19: 3366390 | H19: 2866390 | I19: 2799200 | J19: 500000 | K19: 1099 | L19: The project will make upgrades to the Town‚Äôs distribution system and will include an interconnection between Four States and Monongah. The project also includes a water line extension to the Harter Hill area that will serve five (5) new customers. The project will consist of the installation of approximately 18,900 LF of 6"" and 18,000 LF of 2"" water line; 10,000 LF of ¬æ"" service line replacement; 28 valves; two (2) PRV Stations; 12 fire hydrants; two (2) solenoid master meters; 13 leak detection meters; 465 radio-read meters; all necessary piping, valves and appurtenances. | M19: Yes | N19: 18 | O19: 65 | P19: Yes | Q19: West Virginia | R19: 2023
A20: Marion | B20: Grant Town, Town of | C20: NA | D20: NA | E20: Water System Improvements | F20: General | G20: 3825000 | H20: 2825000 | I20: No Information | J20: No Information | K20: 1240 | L20: This Preliminary Application is to replace water line, booster stations and water storage tank in the Town of Grant Town. The project will consist of the installation of approximately 2.9 miles (15,125 LF) of 8""through 2"" waterline; replace two (2) booster stations; and replace the existing 100,000-gallon tank with a new 200,000- gallon tank; and necessary valves and appurtenances. | M20: Yes | N20: 19 | O20: 65 | P20: No | Q20: West Virginia | R20: 2023
A21: Preston | B21: Terra Alta Municipal Water Dept. | C21: NA | D21: NA | E21: Water System Extensions and Improvements | F21: General | G21: 6250000 | H21: 4800000 | I21: No Information | J21: No Information | K21: 1856 | L21: This preliminary application is to extend water service to 25 new customers and to upgrade/replace the water system in the Town of Terra Alta. The water distribution section of the project will consist of the installation of approximately 1.5 miles (8,100 LF) of 2"" and 6.2 miles (32,800 LF) of 8"" water line; replace the 200,000 gallon Goodwill water storage tank; replace the Corinth water storage tank altitude valve; replace all meters with radio read meters; purchase a compact excavator, equipment trailer and a service dump truck; and all necessary valves, controls and appurtenances. The water treatment portion of the project will consist of a new high | M21: Yes | N21: 20 | O21: 65 | P21: No | Q21: West Virginia | R21: 2023
A22: Mineral | B22: New Creek Water Association | C22: NA | D22: NA | E22: Water System Improvements | F22: General | G22: 5673000 | H22: 5673000 | I22: No Information | J22: No Information | K22: 3043 | L22: This project proposes to make several upgrades around the water system including waterline replacements, waterline extensions, tank replacement, Booster Pump Station Upgrades and various other system upgrades. | M22: Yes | N22: 21 | O22: 65 | P22: No | Q22: West Virginia | R22: 2023
A23: Marion | B23: Rivesville, Town of | C23: NA | D23: NA | E23: Fairmont to Rivesville Water Supply Line Project | F23: General | G23: 3206307 | H23: 500000 | I23: No Information | J23: No Information | K23: 1443 | L23: The proposed project includes replacing the deteriorated 8‚Äù main supply line with a 12‚Äù line that will connect to the City of Fairmont‚Äôs 16‚Äù main. This project will consist constructing 10,500 feet (2 mi) of 12‚Äù water line and 300 feet of 8‚Äù water line within a stream crossing, 350 feet of steel casing and 6 gate valves. The City of Fairmont provides water to the Town of Rivesville. The intent is to ultimately transfer ownership of a portion of the line to the City of Fairmont. | M23: Yes | N23: 22 | O23: 60 | P23: No | Q23: West Virginia | R23: 2023
A24: Fayette | B24: Pax, Town of | C24: NA | D24: NA | E24: Water System Upgrades | F24: General | G24: 1680000 | H24: 1680000 | I24: No Information | J24: No Information | K24: 762 | L24: This project proposes replacing sections of water main between the Beckley Water Company connection point and the Pax water tank. The proposed project will consist of approximately 1.9 miles (10,000 LF) of 6‚Äù PVC, 400 LF of 6‚Äù DIP, 600 LF of 8‚Äù HDPE, 400 LF of 2‚Äù PVC, five stream crossings, five Department of Highway road crossings, and related appurtenances. This will renew the useful life of this critical section of waterline and will continue to distribute treated water for the Town of Pax customers. | M24: Yes | N24: 23 | O24: 60 | P24: No | Q24: West Virginia | R24: 2023
A25: Mason | B25: Mason County PSD | C25: NA | D25: NA | E25: J2Y35 Water System Improvements | F25: General | G25: 1400000 | H25: 500000 | I25: No Information | J25: No Information | K25: 3323 | L25: This project includes Miscellaneous improvements to existing J2Y35 water association water system in order for the Mason County PSD to adequately operate it through feeding it from its system, including 10,000 LF 8 inch transmission line to connect PSD system to J2Y35 tank; 125 gpm booster station near tie in; replace J2Y35 89,300 gallon tank; PRV valve vault for existing customers fed through 22nd Street master meter | M25: Yes | N25: 24 | O25: 60 | P25: No | Q25: West Virginia | R25: 2023
A26: Upshur | B26: Hodgesville PSD | C26: NA | D26: NA | E26: Water System Improvements & Extension | F26: General | G26: 7000000 | H26: 2320000 | I26: No Information | J26: No Information | K26: 2887 | L26: This project will replace approximately 175 service lines in the existing system. It will also include an extension on the Upper Peck's Run Road to serve an additional five customers. The project includes the installation of two 100,000 gallon water tanks as well as a booster pump station. The project also includes the installation of approximately 1200 radio read meters. | M26: Yes | N26: 25 | O26: 60 | P26: No | Q26: West Virginia | R26: 2023
A27: Roane | B27: Walton PSD | C27: NA | D27: NA | E27: Camp Shepard-Quarry Road Water Line Extensions | F27: General | G27: 3459710 | H27: 959710 | I27: No Information | J27: No Information | K27: 1986 | L27: This project will upgrade the line size to the Camp Shepard 4-H camp to provide fire protection and then extend the line out to serve approximately 26 new customers along Wolf Run and Quarry Road. Included will be approximately 3.7 miles of water line , (2) fire hydrants, a booster station, (1) 50,000 gallon water storage tank, and all necessary valves and appurtenances. They also plan to repaint the 100,000 gallon Walton water storage tank and refurbish the Gandeeville, Ambler Ridge, and Long Ridge water storage tanks. | M27: Yes | N27: 26 | O27: 55 | P27: No | Q27: West Virginia | R27: 2023
A28: Summers | B28: Jumping Branch Nimitz PSD | C28: NA | D28: NA | E28: Broomstraw Rd./Mark Meador Rd. Extension | F28: General | G28: 4811800 | H28: 400000 | I28: No Information | J28: No Information | K28: 1414 | L28: This project will provide water service to the Broomstraw Rd. and Mark Meador Rd. areas of western Summers County. Residents experience low water quality and poor quality water issues in existing private wells. In addition, many residents haul water, use cisterns, and some report fecal contaminants in wells. | M28: Yes | N28: 27 | O28: 53 | P28: No | Q28: West Virginia | R28: 2023
A29: Summers | B29: Jumping Branch Nimitz PSD | C29: NA | D29: NA | E29: Madams Creek Waterline Ext. | F29: General | G29: 4418500 | H29: No Information | I29: No Information | J29: No Information | K29: 1414 | L29: To provide water service to the Madams Creek Rd. area of western Summers Co. Residents experience low water quality and poor quality water issues in existing private wells. In addition, man residents haul water, use cisterns, and some report fecal contaminants in wells. | M29: Yes | N29: 28 | O29: 53 | P29: No | Q29: West Virginia | R29: 2023
A30: Webster | B30: Cowen PSD | C30: NA | D30: NA | E30: Rt. 82 Water Line Extension Project | F30: General | G30: 4500000 | H30: 3000000 | I30: No Information | J30: No Information | K30: 2796 | L30: This project consists of extending public water service and providing fire service to approximately 55 proposed customers along Rt. 82 in Webster County. | M30: Yes | N30: 29 | O30: 53 | P30: No | Q30: West Virginia | R30: 2023
A31: Harrison | B31: Anmoore, Town of | C31: NA | D31: NA | E31: Water System Improvements | F31: General | G31: 3300000 | H31: 2300000 | I31: No Information | J31: No Information | K31: 951 | L31: This Preliminary Application is to replace existing water line in the Town of Anmoore with approximately 5.2 miles (27,380 LF) of 8"" thru 2‚Äù water line, approximately 1.5 miles of service line (8,080 LF) and approximately 456 new radio read meters. | M31: Yes | N31: 30 | O31: 50 | P31: No | Q31: West Virginia | R31: 2023
A32: Pocahontas | B32: Marlinton, Town of | C32: NA | D32: NA | E32: Phase II Water System Improvements | F32: General | G32: 4500000 | H32: 3500000 | I32: No Information | J32: No Information | K32: 1362 | L32: This project is Phase 2 for Marlinton‚Äôs water distribution system improvements. The project will replace approximately 1.9 miles of existing 4-inch water mains with 6- inch water line and replace approximately 1.9 miles of existing 1.25-inch water line with 2-inch water line. Also included will be to installation of 41 valves, 20 fire hydrants, 10 leak detector meters, replace 300 meters/wells/setters, and all other necessary valves and appurtenances. | M32: Yes | N32: 31 | O32: 50 | P32: No | Q32: West Virginia | R32: 2023
A33: Webster | B33: Cowen PSD | C33: NA | D33: NA | E33: Ph III Water System Rehabilitation Project | F33: General | G33: 11580000 | H33: 2580000 | I33: No Information | J33: No Information | K33: 3372 | L33: Project will remove and replace approx. 17,050 lf of water lines ranging in size from 2"" to 10"" and rehabilitate the existing WTP and upgrade the capacity from 600 GPM to 1,200 GPM | M33: Yes | N33: 32 | O33: 50 | P33: No | Q33: West Virginia | R33: 2023
A34: Mingo | B34: Williamson, City of | C34: NA | D34: NA | E34: Water System Upgrade Project | F34: General | G34: 12578000 | H34: 12578000 | I34: No Information | J34: No Information | K34: 4183 | L34: This project will upgrade the water treatment, storage and distribution system. Upgrades will consist of the installation of (3) 2,500 GPM treatment high service pumps, approx. 2.86 miles of 24-inch and smaller diameter mains, a 500 GPM booster pump station, four new water storage tanks, rehab of existing tank, numerous pressure reducing stations, back up generators for TP and booster pump stations, telemetry, hydrants, valves, meters | M34: Yes | N34: 33 | O34: 50 | P34: No | Q34: West Virginia | R34: 2023
A35: McDowell | B35: McDowell County PSD | C35: NA | D35: NA | E35: Bradshaw | F35: General | G35: 2000000 | H35: 100000 | I35: No Information | J35: No Information | K35: 1854 | L35: This project proposes that the Bradshaw water system will be connected to the McDowell County PSD Bartley water distribution system that runs through town, and the water will be supplied by the MCPSD Bartley WTP. In addition it will involve the decommissioning of the Bradshaw Water Treatment Plant and the Bradshaw water tank. This project will result in the consolidation of Bradshaw Water Works and McDowell Co. PSD ‚Äì Bartley. | M35: Yes | N35: 34 | O35: 50 | P35: No | Q35: West Virginia | R35: 2023
A36: Fayette | B36: New Haven PSD | C36: NA | D36: NA | E36: Contract 18 - Sunday Rd./Confluence/Elliott Cutoff area. | F36: General | G36: 2933635 | H36: 2493325 | I36: 753884 | J36: 376942 | K36: 4409 | L36: Water line extension to Sunday Rd./Confluence/Elliot Cufoff area, including possible Stringtown connector & Clifty connector. Approximately 67 new customers. | M36: Yes | N36: 35 | O36: 48 | P36: Yes | Q36: West Virginia | R36: 2023
A37: Fayette | B37: New Haven PSD | C37: NA | D37: NA | E37: Contract 19 - Ramsey Extension | F37: General | G37: 4841686 | H37: 3927250 | I37: 1089841 | J37: 337600 | K37: 4438 | L37: Water line extension to Cane Branch, Ramsey, Hawver Rd., South Miller Ridge, Arrowwood Rd., Dotson Ridge & Lower Dotson Ridge, Whispering Pines. Approximately 73 new customers. | M37: Yes | N37: 36 | O37: 48 | P37: Yes | Q37: West Virginia | R37: 2023
A38: Greenbrier | B38: Greenbrier County PSD #2 | C38: NA | D38: NA | E38: Ph II- Sam Black Water Line Extension | F38: General | G38: 17000000 | H38: 9000000 | I38: No Information | J38: No Information | K38: 2326 | L38: This project extends water service to approximately 475 new customers from Charmco to Rainelle and from Sam Black Church to Asbury in Greenbrier County. The project includes approximately 17 miles of 2-inch to 8-inch distribution line, two (2) booster stations, one (1) 100,000-gallon water storage tank, one (1) 300,000 gallon water storage tank, 50 gate valves, 40 fire hydrants, 30 flushing hydrants and other appurtenances. | M38: Yes | N38: 37 | O38: 45 | P38: No | Q38: West Virginia | R38: 2023
A39: Mercer | B39: Lashmeet PSD | C39: NA | D39: NA | E39: Mary Branch Water Extension | F39: General | G39: 2146050 | H39: 971453 | I39: 1279921 | J39: 214753 | K39: 3794 | L39: Extension of public water to the Mary Branch area of Mercer County, West Virginia. 4 miles. Approximately 42 new customers. | M39: Yes | N39: 38 | O39: 40 | P39: Yes | Q39: West Virginia | R39: 2023
A40: Brooke | B40: Hammond PSD | C40: NA | D40: NA | E40: Water System Improvements | F40: General | G40: 6174000 | H40: 5674000 | I40: No Information | J40: No Information | K40: 2196 | L40: This project includes system improvements to the distribution systems and the water treatment plant. This includes water main replacement, replacing exiting meters with new AMR meters, replacing shut off valves, pump station improvements and upgrades to existing water storage tanks. Water treatment plant improvements include replacing the sedimentation basin, filter media replacement, automatic valve installation, installation of a permanent generator and pump replacement. | M40: Yes | N40: 39 | O40: 40 | P40: No | Q40: West Virginia | R40: 2023
...
